[2023-04-07 13:00:39,529] INFO _log() L224  127.0.0.1 - - [07/Apr/2023 13:00:39] "GET /openapi/openapi.json HTTP/1.1" 200 - - call_trace=C:\PUC-RIO\Sprint-1\BackEnd\puc-rio-mvp-sprint-1-back-end\venv\Lib\site-packages\werkzeug\_internal.py L224 
[2023-04-07 13:00:39,558] INFO _log() L224  127.0.0.1 - - [07/Apr/2023 13:00:39] "[36mGET /openapi/static/images/swagger.svg HTTP/1.1[0m" 304 - - call_trace=C:\PUC-RIO\Sprint-1\BackEnd\puc-rio-mvp-sprint-1-back-end\venv\Lib\site-packages\werkzeug\_internal.py L224 
[2023-04-07 13:00:48,665] INFO _log() L224  127.0.0.1 - - [07/Apr/2023 13:00:48] "GET /servicos HTTP/1.1" 200 - - call_trace=C:\PUC-RIO\Sprint-1\BackEnd\puc-rio-mvp-sprint-1-back-end\venv\Lib\site-packages\werkzeug\_internal.py L224 
[2023-04-07 13:01:03,302] WARNING get_servico() L455  Erro ao buscar o servico 'pintar a unha', Serviço não encontrado na base :/ - call_trace=C:\PUC-RIO\Sprint-1\BackEnd\puc-rio-mvp-sprint-1-back-end\app.py L455 
[2023-04-07 13:01:03,303] INFO _log() L224  127.0.0.1 - - [07/Apr/2023 13:01:03] "[33mGET /servico?descricao=pintar%20a%20unha HTTP/1.1[0m" 404 - - call_trace=C:\PUC-RIO\Sprint-1\BackEnd\puc-rio-mvp-sprint-1-back-end\venv\Lib\site-packages\werkzeug\_internal.py L224 
[2023-04-07 13:01:21,946] WARNING get_servico() L455  Erro ao buscar o servico 'escova', Serviço não encontrado na base :/ - call_trace=C:\PUC-RIO\Sprint-1\BackEnd\puc-rio-mvp-sprint-1-back-end\app.py L455 
[2023-04-07 13:01:21,946] INFO _log() L224  127.0.0.1 - - [07/Apr/2023 13:01:21] "[33mGET /servico?descricao=escova HTTP/1.1[0m" 404 - - call_trace=C:\PUC-RIO\Sprint-1\BackEnd\puc-rio-mvp-sprint-1-back-end\venv\Lib\site-packages\werkzeug\_internal.py L224 
[2023-04-07 13:01:28,513] ERROR log_exception() L1449 Exception on /servico [GET] - call_trace=C:\PUC-RIO\Sprint-1\BackEnd\puc-rio-mvp-sprint-1-back-end\venv\Lib\site-packages\flask\app.py L1449
Traceback (most recent call last):
  File "C:\PUC-RIO\Sprint-1\BackEnd\puc-rio-mvp-sprint-1-back-end\venv\Lib\site-packages\flask\app.py", line 2073, in wsgi_app
    response = self.full_dispatch_request()
               ^^^^^^^^^^^^^^^^^^^^^^^^^^^^
  File "C:\PUC-RIO\Sprint-1\BackEnd\puc-rio-mvp-sprint-1-back-end\venv\Lib\site-packages\flask\app.py", line 1519, in full_dispatch_request
    rv = self.handle_user_exception(e)
         ^^^^^^^^^^^^^^^^^^^^^^^^^^^^^
  File "C:\PUC-RIO\Sprint-1\BackEnd\puc-rio-mvp-sprint-1-back-end\venv\Lib\site-packages\flask_cors\extension.py", line 165, in wrapped_function
    return cors_after_request(app.make_response(f(*args, **kwargs)))
                                                ^^^^^^^^^^^^^^^^^^
  File "C:\PUC-RIO\Sprint-1\BackEnd\puc-rio-mvp-sprint-1-back-end\venv\Lib\site-packages\flask\app.py", line 1517, in full_dispatch_request
    rv = self.dispatch_request()
         ^^^^^^^^^^^^^^^^^^^^^^^
  File "C:\PUC-RIO\Sprint-1\BackEnd\puc-rio-mvp-sprint-1-back-end\venv\Lib\site-packages\flask\app.py", line 1503, in dispatch_request
    return self.ensure_sync(self.view_functions[rule.endpoint])(**req.view_args)
           ^^^^^^^^^^^^^^^^^^^^^^^^^^^^^^^^^^^^^^^^^^^^^^^^^^^^^^^^^^^^^^^^^^^^^
  File "C:\PUC-RIO\Sprint-1\BackEnd\puc-rio-mvp-sprint-1-back-end\venv\Lib\site-packages\flask_openapi3\scaffold.py", line 109, in wrapper
    resp = _do_wrapper(
           ^^^^^^^^^^^^
  File "C:\PUC-RIO\Sprint-1\BackEnd\puc-rio-mvp-sprint-1-back-end\venv\Lib\site-packages\flask_openapi3\do_wrapper.py", line 135, in _do_wrapper
    response = func(**request_kwargs)
               ^^^^^^^^^^^^^^^^^^^^^^
  File "C:\PUC-RIO\Sprint-1\BackEnd\puc-rio-mvp-sprint-1-back-end\app.py", line 458, in get_servico
    logger.debug(f"Serviço encontrado: '{servico.nome}'")
                                         ^^^^^^^^^^^^
AttributeError: 'Servico' object has no attribute 'nome'
[2023-04-07 13:01:28,522] INFO _log() L224  127.0.0.1 - - [07/Apr/2023 13:01:28] "[35m[1mGET /servico?descricao=Escova HTTP/1.1[0m" 500 - - call_trace=C:\PUC-RIO\Sprint-1\BackEnd\puc-rio-mvp-sprint-1-back-end\venv\Lib\site-packages\werkzeug\_internal.py L224 
[2023-04-07 13:02:01,599] INFO _log() L224   * Running on all addresses (0.0.0.0)
   WARNING: This is a development server. Do not use it in a production deployment.
 * Running on http://127.0.0.1:5000
 * Running on http://192.168.15.138:5000 (Press CTRL+C to quit) - call_trace=C:\PUC-RIO\Sprint-1\BackEnd\puc-rio-mvp-sprint-1-back-end\venv\Lib\site-packages\werkzeug\_internal.py L224 
[2023-04-07 13:02:08,184] INFO _log() L224  127.0.0.1 - - [07/Apr/2023 13:02:08] "GET /openapi/swagger HTTP/1.1" 200 - - call_trace=C:\PUC-RIO\Sprint-1\BackEnd\puc-rio-mvp-sprint-1-back-end\venv\Lib\site-packages\werkzeug\_internal.py L224 
[2023-04-07 13:02:08,313] INFO _log() L224  127.0.0.1 - - [07/Apr/2023 13:02:08] "[36mGET /openapi/static/css/swagger-ui.css HTTP/1.1[0m" 304 - - call_trace=C:\PUC-RIO\Sprint-1\BackEnd\puc-rio-mvp-sprint-1-back-end\venv\Lib\site-packages\werkzeug\_internal.py L224 
[2023-04-07 13:02:08,314] INFO _log() L224  127.0.0.1 - - [07/Apr/2023 13:02:08] "[36mGET /openapi/static/js/swagger-ui-bundle.js HTTP/1.1[0m" 304 - - call_trace=C:\PUC-RIO\Sprint-1\BackEnd\puc-rio-mvp-sprint-1-back-end\venv\Lib\site-packages\werkzeug\_internal.py L224 
[2023-04-07 13:02:08,315] INFO _log() L224  127.0.0.1 - - [07/Apr/2023 13:02:08] "[36mGET /openapi/static/js/swagger-ui-standalone-preset.js HTTP/1.1[0m" 304 - - call_trace=C:\PUC-RIO\Sprint-1\BackEnd\puc-rio-mvp-sprint-1-back-end\venv\Lib\site-packages\werkzeug\_internal.py L224 
[2023-04-07 13:02:08,383] INFO _log() L224  127.0.0.1 - - [07/Apr/2023 13:02:08] "GET /openapi/openapi.json HTTP/1.1" 200 - - call_trace=C:\PUC-RIO\Sprint-1\BackEnd\puc-rio-mvp-sprint-1-back-end\venv\Lib\site-packages\werkzeug\_internal.py L224 
[2023-04-07 13:02:08,441] INFO _log() L224  127.0.0.1 - - [07/Apr/2023 13:02:08] "[36mGET /openapi/static/images/swagger.svg HTTP/1.1[0m" 304 - - call_trace=C:\PUC-RIO\Sprint-1\BackEnd\puc-rio-mvp-sprint-1-back-end\venv\Lib\site-packages\werkzeug\_internal.py L224 
[2023-04-07 13:02:17,863] INFO _log() L224  127.0.0.1 - - [07/Apr/2023 13:02:17] "GET /servico?descricao=Escova HTTP/1.1" 200 - - call_trace=C:\PUC-RIO\Sprint-1\BackEnd\puc-rio-mvp-sprint-1-back-end\venv\Lib\site-packages\werkzeug\_internal.py L224 
[2023-04-07 13:03:12,295] ERROR log_exception() L1449 Exception on /servico [PUT] - call_trace=C:\PUC-RIO\Sprint-1\BackEnd\puc-rio-mvp-sprint-1-back-end\venv\Lib\site-packages\flask\app.py L1449
Traceback (most recent call last):
  File "C:\PUC-RIO\Sprint-1\BackEnd\puc-rio-mvp-sprint-1-back-end\venv\Lib\site-packages\flask\app.py", line 2073, in wsgi_app
    response = self.full_dispatch_request()
               ^^^^^^^^^^^^^^^^^^^^^^^^^^^^
  File "C:\PUC-RIO\Sprint-1\BackEnd\puc-rio-mvp-sprint-1-back-end\venv\Lib\site-packages\flask\app.py", line 1519, in full_dispatch_request
    rv = self.handle_user_exception(e)
         ^^^^^^^^^^^^^^^^^^^^^^^^^^^^^
  File "C:\PUC-RIO\Sprint-1\BackEnd\puc-rio-mvp-sprint-1-back-end\venv\Lib\site-packages\flask_cors\extension.py", line 165, in wrapped_function
    return cors_after_request(app.make_response(f(*args, **kwargs)))
                                                ^^^^^^^^^^^^^^^^^^
  File "C:\PUC-RIO\Sprint-1\BackEnd\puc-rio-mvp-sprint-1-back-end\venv\Lib\site-packages\flask\app.py", line 1517, in full_dispatch_request
    rv = self.dispatch_request()
         ^^^^^^^^^^^^^^^^^^^^^^^
  File "C:\PUC-RIO\Sprint-1\BackEnd\puc-rio-mvp-sprint-1-back-end\venv\Lib\site-packages\flask\app.py", line 1503, in dispatch_request
    return self.ensure_sync(self.view_functions[rule.endpoint])(**req.view_args)
           ^^^^^^^^^^^^^^^^^^^^^^^^^^^^^^^^^^^^^^^^^^^^^^^^^^^^^^^^^^^^^^^^^^^^^
  File "C:\PUC-RIO\Sprint-1\BackEnd\puc-rio-mvp-sprint-1-back-end\venv\Lib\site-packages\flask_openapi3\scaffold.py", line 273, in wrapper
    resp = _do_wrapper(
           ^^^^^^^^^^^^
  File "C:\PUC-RIO\Sprint-1\BackEnd\puc-rio-mvp-sprint-1-back-end\venv\Lib\site-packages\flask_openapi3\do_wrapper.py", line 135, in _do_wrapper
    response = func(**request_kwargs)
               ^^^^^^^^^^^^^^^^^^^^^^
  File "C:\PUC-RIO\Sprint-1\BackEnd\puc-rio-mvp-sprint-1-back-end\app.py", line 374, in put_servico
    servico = Servico(
              ^^^^^^^^
TypeError: __init__() got an unexpected keyword argument 'id'
[2023-04-07 13:03:12,299] INFO _log() L224  127.0.0.1 - - [07/Apr/2023 13:03:12] "[35m[1mPUT /servico HTTP/1.1[0m" 500 - - call_trace=C:\PUC-RIO\Sprint-1\BackEnd\puc-rio-mvp-sprint-1-back-end\venv\Lib\site-packages\werkzeug\_internal.py L224 
[2023-04-07 13:05:54,923] INFO _log() L224   * Running on all addresses (0.0.0.0)
   WARNING: This is a development server. Do not use it in a production deployment.
 * Running on http://127.0.0.1:5000
 * Running on http://192.168.15.138:5000 (Press CTRL+C to quit) - call_trace=C:\PUC-RIO\Sprint-1\BackEnd\puc-rio-mvp-sprint-1-back-end\venv\Lib\site-packages\werkzeug\_internal.py L224 
[2023-04-07 13:06:00,618] INFO _log() L224  127.0.0.1 - - [07/Apr/2023 13:06:00] "GET /openapi/swagger HTTP/1.1" 200 - - call_trace=C:\PUC-RIO\Sprint-1\BackEnd\puc-rio-mvp-sprint-1-back-end\venv\Lib\site-packages\werkzeug\_internal.py L224 
[2023-04-07 13:06:00,714] INFO _log() L224  127.0.0.1 - - [07/Apr/2023 13:06:00] "[36mGET /openapi/static/css/swagger-ui.css HTTP/1.1[0m" 304 - - call_trace=C:\PUC-RIO\Sprint-1\BackEnd\puc-rio-mvp-sprint-1-back-end\venv\Lib\site-packages\werkzeug\_internal.py L224 
[2023-04-07 13:06:00,721] INFO _log() L224  127.0.0.1 - - [07/Apr/2023 13:06:00] "[36mGET /openapi/static/js/swagger-ui-standalone-preset.js HTTP/1.1[0m" 304 - - call_trace=C:\PUC-RIO\Sprint-1\BackEnd\puc-rio-mvp-sprint-1-back-end\venv\Lib\site-packages\werkzeug\_internal.py L224 
