[2023-04-05 00:26:25,900] ERROR log_exception() L1449 Exception on /agendamento [POST] - call_trace=C:\PUC-RIO\Sprint-1\BackEnd\puc-rio-mvp-sprint-1-back-end\venv\Lib\site-packages\flask\app.py L1449
Traceback (most recent call last):
  File "C:\PUC-RIO\Sprint-1\BackEnd\puc-rio-mvp-sprint-1-back-end\venv\Lib\site-packages\flask\app.py", line 2073, in wsgi_app
    response = self.full_dispatch_request()
               ^^^^^^^^^^^^^^^^^^^^^^^^^^^^
  File "C:\PUC-RIO\Sprint-1\BackEnd\puc-rio-mvp-sprint-1-back-end\venv\Lib\site-packages\flask\app.py", line 1519, in full_dispatch_request
    rv = self.handle_user_exception(e)
         ^^^^^^^^^^^^^^^^^^^^^^^^^^^^^
  File "C:\PUC-RIO\Sprint-1\BackEnd\puc-rio-mvp-sprint-1-back-end\venv\Lib\site-packages\flask_cors\extension.py", line 165, in wrapped_function
    return cors_after_request(app.make_response(f(*args, **kwargs)))
                                                ^^^^^^^^^^^^^^^^^^
  File "C:\PUC-RIO\Sprint-1\BackEnd\puc-rio-mvp-sprint-1-back-end\venv\Lib\site-packages\flask\app.py", line 1517, in full_dispatch_request
    rv = self.dispatch_request()
         ^^^^^^^^^^^^^^^^^^^^^^^
  File "C:\PUC-RIO\Sprint-1\BackEnd\puc-rio-mvp-sprint-1-back-end\venv\Lib\site-packages\flask\app.py", line 1503, in dispatch_request
    return self.ensure_sync(self.view_functions[rule.endpoint])(**req.view_args)
           ^^^^^^^^^^^^^^^^^^^^^^^^^^^^^^^^^^^^^^^^^^^^^^^^^^^^^^^^^^^^^^^^^^^^^
  File "C:\PUC-RIO\Sprint-1\BackEnd\puc-rio-mvp-sprint-1-back-end\venv\Lib\site-packages\flask_openapi3\scaffold.py", line 191, in wrapper
    resp = _do_wrapper(
           ^^^^^^^^^^^^
  File "C:\PUC-RIO\Sprint-1\BackEnd\puc-rio-mvp-sprint-1-back-end\venv\Lib\site-packages\flask_openapi3\do_wrapper.py", line 135, in _do_wrapper
    response = func(**request_kwargs)
               ^^^^^^^^^^^^^^^^^^^^^^
  File "C:\PUC-RIO\Sprint-1\BackEnd\puc-rio-mvp-sprint-1-back-end\app.py", line 47, in add_agendamento
    data_agenda=  datetime.strptime(form.data_agenda, '%y/%m/%d %H:%M:%S') ,
          ^^^^^^^^^^^^^^^^^^^^^^^^^^^^^^^^^^^^^^^^^^^^^^^^^^^^^^^^
  File "C:\Users\edumi\AppData\Local\Programs\Python\Python311\Lib\_strptime.py", line 568, in _strptime_datetime
    tt, fraction, gmtoff_fraction = _strptime(data_string, format)
                                    ^^^^^^^^^^^^^^^^^^^^^^^^^^^^^^
  File "C:\Users\edumi\AppData\Local\Programs\Python\Python311\Lib\_strptime.py", line 349, in _strptime
    raise ValueError("time data %r does not match format %r" %
ValueError: time data '2023-04-01 08:00:00' does not match format '%y/%m/%d %H:%M:%S'
[2023-04-05 00:26:25,909] INFO _log() L224  127.0.0.1 - - [05/Apr/2023 00:26:25] "[35m[1mPOST /agendamento HTTP/1.1[0m" 500 - - call_trace=C:\PUC-RIO\Sprint-1\BackEnd\puc-rio-mvp-sprint-1-back-end\venv\Lib\site-packages\werkzeug\_internal.py L224 
[2023-04-05 00:28:13,806] INFO _log() L224   * Running on all addresses (0.0.0.0)
   WARNING: This is a development server. Do not use it in a production deployment.
 * Running on http://127.0.0.1:5000
 * Running on http://192.168.15.138:5000 (Press CTRL+C to quit) - call_trace=C:\PUC-RIO\Sprint-1\BackEnd\puc-rio-mvp-sprint-1-back-end\venv\Lib\site-packages\werkzeug\_internal.py L224 
[2023-04-05 00:28:17,392] ERROR log_exception() L1449 Exception on /agendamento [POST] - call_trace=C:\PUC-RIO\Sprint-1\BackEnd\puc-rio-mvp-sprint-1-back-end\venv\Lib\site-packages\flask\app.py L1449
Traceback (most recent call last):
  File "C:\PUC-RIO\Sprint-1\BackEnd\puc-rio-mvp-sprint-1-back-end\venv\Lib\site-packages\flask\app.py", line 2073, in wsgi_app
    response = self.full_dispatch_request()
               ^^^^^^^^^^^^^^^^^^^^^^^^^^^^
  File "C:\PUC-RIO\Sprint-1\BackEnd\puc-rio-mvp-sprint-1-back-end\venv\Lib\site-packages\flask\app.py", line 1519, in full_dispatch_request
    rv = self.handle_user_exception(e)
         ^^^^^^^^^^^^^^^^^^^^^^^^^^^^^
  File "C:\PUC-RIO\Sprint-1\BackEnd\puc-rio-mvp-sprint-1-back-end\venv\Lib\site-packages\flask_cors\extension.py", line 165, in wrapped_function
    return cors_after_request(app.make_response(f(*args, **kwargs)))
                                                ^^^^^^^^^^^^^^^^^^
  File "C:\PUC-RIO\Sprint-1\BackEnd\puc-rio-mvp-sprint-1-back-end\venv\Lib\site-packages\flask\app.py", line 1517, in full_dispatch_request
    rv = self.dispatch_request()
         ^^^^^^^^^^^^^^^^^^^^^^^
  File "C:\PUC-RIO\Sprint-1\BackEnd\puc-rio-mvp-sprint-1-back-end\venv\Lib\site-packages\flask\app.py", line 1503, in dispatch_request
    return self.ensure_sync(self.view_functions[rule.endpoint])(**req.view_args)
           ^^^^^^^^^^^^^^^^^^^^^^^^^^^^^^^^^^^^^^^^^^^^^^^^^^^^^^^^^^^^^^^^^^^^^
  File "C:\PUC-RIO\Sprint-1\BackEnd\puc-rio-mvp-sprint-1-back-end\venv\Lib\site-packages\flask_openapi3\scaffold.py", line 191, in wrapper
    resp = _do_wrapper(
           ^^^^^^^^^^^^
  File "C:\PUC-RIO\Sprint-1\BackEnd\puc-rio-mvp-sprint-1-back-end\venv\Lib\site-packages\flask_openapi3\do_wrapper.py", line 135, in _do_wrapper
    response = func(**request_kwargs)
               ^^^^^^^^^^^^^^^^^^^^^^
  File "C:\PUC-RIO\Sprint-1\BackEnd\puc-rio-mvp-sprint-1-back-end\app.py", line 46, in add_agendamento
    print( datetime.strptime(form.data_agenda, '%m/%d/%y %H:%M:%S') )
           ^^^^^^^^^^^^^^^^^^^^^^^^^^^^^^^^^^^^^^^^^^^^^^^^^^^^^^^^
  File "C:\Users\edumi\AppData\Local\Programs\Python\Python311\Lib\_strptime.py", line 568, in _strptime_datetime
    tt, fraction, gmtoff_fraction = _strptime(data_string, format)
                                    ^^^^^^^^^^^^^^^^^^^^^^^^^^^^^^
  File "C:\Users\edumi\AppData\Local\Programs\Python\Python311\Lib\_strptime.py", line 349, in _strptime
    raise ValueError("time data %r does not match format %r" %
ValueError: time data '2023-04-01 08:00:00' does not match format '%m/%d/%y %H:%M:%S'
[2023-04-05 00:28:17,397] INFO _log() L224  127.0.0.1 - - [05/Apr/2023 00:28:17] "[35m[1mPOST /agendamento HTTP/1.1[0m" 500 - - call_trace=C:\PUC-RIO\Sprint-1\BackEnd\puc-rio-mvp-sprint-1-back-end\venv\Lib\site-packages\werkzeug\_internal.py L224 
[2023-04-05 00:29:37,661] ERROR log_exception() L1449 Exception on /agendamento [POST] - call_trace=C:\PUC-RIO\Sprint-1\BackEnd\puc-rio-mvp-sprint-1-back-end\venv\Lib\site-packages\flask\app.py L1449
Traceback (most recent call last):
  File "C:\PUC-RIO\Sprint-1\BackEnd\puc-rio-mvp-sprint-1-back-end\venv\Lib\site-packages\flask\app.py", line 2073, in wsgi_app
    response = self.full_dispatch_request()
               ^^^^^^^^^^^^^^^^^^^^^^^^^^^^
  File "C:\PUC-RIO\Sprint-1\BackEnd\puc-rio-mvp-sprint-1-back-end\venv\Lib\site-packages\flask\app.py", line 1519, in full_dispatch_request
    rv = self.handle_user_exception(e)
         ^^^^^^^^^^^^^^^^^^^^^^^^^^^^^
  File "C:\PUC-RIO\Sprint-1\BackEnd\puc-rio-mvp-sprint-1-back-end\venv\Lib\site-packages\flask_cors\extension.py", line 165, in wrapped_function
    return cors_after_request(app.make_response(f(*args, **kwargs)))
                                                ^^^^^^^^^^^^^^^^^^
  File "C:\PUC-RIO\Sprint-1\BackEnd\puc-rio-mvp-sprint-1-back-end\venv\Lib\site-packages\flask\app.py", line 1517, in full_dispatch_request
    rv = self.dispatch_request()
         ^^^^^^^^^^^^^^^^^^^^^^^
  File "C:\PUC-RIO\Sprint-1\BackEnd\puc-rio-mvp-sprint-1-back-end\venv\Lib\site-packages\flask\app.py", line 1503, in dispatch_request
    return self.ensure_sync(self.view_functions[rule.endpoint])(**req.view_args)
           ^^^^^^^^^^^^^^^^^^^^^^^^^^^^^^^^^^^^^^^^^^^^^^^^^^^^^^^^^^^^^^^^^^^^^
  File "C:\PUC-RIO\Sprint-1\BackEnd\puc-rio-mvp-sprint-1-back-end\venv\Lib\site-packages\flask_openapi3\scaffold.py", line 191, in wrapper
    resp = _do_wrapper(
           ^^^^^^^^^^^^
  File "C:\PUC-RIO\Sprint-1\BackEnd\puc-rio-mvp-sprint-1-back-end\venv\Lib\site-packages\flask_openapi3\do_wrapper.py", line 135, in _do_wrapper
    response = func(**request_kwargs)
               ^^^^^^^^^^^^^^^^^^^^^^
  File "C:\PUC-RIO\Sprint-1\BackEnd\puc-rio-mvp-sprint-1-back-end\app.py", line 46, in add_agendamento
    print( datetime.strptime(form.data_agenda, '%m/%d/%y %H:%M:%S') )
           ^^^^^^^^^^^^^^^^^^^^^^^^^^^^^^^^^^^^^^^^^^^^^^^^^^^^^^^^
  File "C:\Users\edumi\AppData\Local\Programs\Python\Python311\Lib\_strptime.py", line 568, in _strptime_datetime
    tt, fraction, gmtoff_fraction = _strptime(data_string, format)
                                    ^^^^^^^^^^^^^^^^^^^^^^^^^^^^^^
  File "C:\Users\edumi\AppData\Local\Programs\Python\Python311\Lib\_strptime.py", line 349, in _strptime
    raise ValueError("time data %r does not match format %r" %
ValueError: time data '2023-04-01 08:00:00' does not match format '%m/%d/%y %H:%M:%S'
[2023-04-05 00:29:37,663] INFO _log() L224  127.0.0.1 - - [05/Apr/2023 00:29:37] "[35m[1mPOST /agendamento HTTP/1.1[0m" 500 - - call_trace=C:\PUC-RIO\Sprint-1\BackEnd\puc-rio-mvp-sprint-1-back-end\venv\Lib\site-packages\werkzeug\_internal.py L224 
[2023-04-05 00:29:47,016] INFO _log() L224   * Running on all addresses (0.0.0.0)
   WARNING: This is a development server. Do not use it in a production deployment.
 * Running on http://127.0.0.1:5000
 * Running on http://192.168.15.138:5000 (Press CTRL+C to quit) - call_trace=C:\PUC-RIO\Sprint-1\BackEnd\puc-rio-mvp-sprint-1-back-end\venv\Lib\site-packages\werkzeug\_internal.py L224 
[2023-04-05 00:29:50,292] INFO _log() L224  127.0.0.1 - - [05/Apr/2023 00:29:50] "GET /openapi/swagger HTTP/1.1" 200 - - call_trace=C:\PUC-RIO\Sprint-1\BackEnd\puc-rio-mvp-sprint-1-back-end\venv\Lib\site-packages\werkzeug\_internal.py L224 
[2023-04-05 00:29:50,406] INFO _log() L224  127.0.0.1 - - [05/Apr/2023 00:29:50] "[36mGET /openapi/static/css/swagger-ui.css HTTP/1.1[0m" 304 - - call_trace=C:\PUC-RIO\Sprint-1\BackEnd\puc-rio-mvp-sprint-1-back-end\venv\Lib\site-packages\werkzeug\_internal.py L224 
