[2023-04-05 00:32:42,274] ERROR log_exception() L1449 Exception on /agendamento [POST] - call_trace=C:\PUC-RIO\Sprint-1\BackEnd\puc-rio-mvp-sprint-1-back-end\venv\Lib\site-packages\flask\app.py L1449
Traceback (most recent call last):
  File "C:\PUC-RIO\Sprint-1\BackEnd\puc-rio-mvp-sprint-1-back-end\venv\Lib\site-packages\flask\app.py", line 2073, in wsgi_app
    response = self.full_dispatch_request()
               ^^^^^^^^^^^^^^^^^^^^^^^^^^^^
  File "C:\PUC-RIO\Sprint-1\BackEnd\puc-rio-mvp-sprint-1-back-end\venv\Lib\site-packages\flask\app.py", line 1519, in full_dispatch_request
    rv = self.handle_user_exception(e)
         ^^^^^^^^^^^^^^^^^^^^^^^^^^^^^
  File "C:\PUC-RIO\Sprint-1\BackEnd\puc-rio-mvp-sprint-1-back-end\venv\Lib\site-packages\flask_cors\extension.py", line 165, in wrapped_function
    return cors_after_request(app.make_response(f(*args, **kwargs)))
                                                ^^^^^^^^^^^^^^^^^^
  File "C:\PUC-RIO\Sprint-1\BackEnd\puc-rio-mvp-sprint-1-back-end\venv\Lib\site-packages\flask\app.py", line 1517, in full_dispatch_request
    rv = self.dispatch_request()
         ^^^^^^^^^^^^^^^^^^^^^^^
  File "C:\PUC-RIO\Sprint-1\BackEnd\puc-rio-mvp-sprint-1-back-end\venv\Lib\site-packages\flask\app.py", line 1503, in dispatch_request
    return self.ensure_sync(self.view_functions[rule.endpoint])(**req.view_args)
           ^^^^^^^^^^^^^^^^^^^^^^^^^^^^^^^^^^^^^^^^^^^^^^^^^^^^^^^^^^^^^^^^^^^^^
  File "C:\PUC-RIO\Sprint-1\BackEnd\puc-rio-mvp-sprint-1-back-end\venv\Lib\site-packages\flask_openapi3\scaffold.py", line 191, in wrapper
    resp = _do_wrapper(
           ^^^^^^^^^^^^
  File "C:\PUC-RIO\Sprint-1\BackEnd\puc-rio-mvp-sprint-1-back-end\venv\Lib\site-packages\flask_openapi3\do_wrapper.py", line 135, in _do_wrapper
    response = func(**request_kwargs)
               ^^^^^^^^^^^^^^^^^^^^^^
  File "C:\PUC-RIO\Sprint-1\BackEnd\puc-rio-mvp-sprint-1-back-end\app.py", line 46, in add_agendamento
    datetime_object = datetime.strptime(form.data_agenda, '%m/%d/%y %H:%M:%S')
                      ^^^^^^^^^^^^^^^^^^^^^^^^^^^^^^^^^^^^^^^^^^^^^^^^^^^^^^^^
  File "C:\Users\edumi\AppData\Local\Programs\Python\Python311\Lib\_strptime.py", line 568, in _strptime_datetime
    tt, fraction, gmtoff_fraction = _strptime(data_string, format)
                                    ^^^^^^^^^^^^^^^^^^^^^^^^^^^^^^
  File "C:\Users\edumi\AppData\Local\Programs\Python\Python311\Lib\_strptime.py", line 349, in _strptime
    raise ValueError("time data %r does not match format %r" %
ValueError: time data '01/04/2023 08:00:00' does not match format '%m/%d/%y %H:%M:%S'
[2023-04-05 00:32:42,283] INFO _log() L224  127.0.0.1 - - [05/Apr/2023 00:32:42] "[35m[1mPOST /agendamento HTTP/1.1[0m" 500 - - call_trace=C:\PUC-RIO\Sprint-1\BackEnd\puc-rio-mvp-sprint-1-back-end\venv\Lib\site-packages\werkzeug\_internal.py L224 
[2023-04-05 00:32:51,057] INFO _log() L224  127.0.0.1 - - [05/Apr/2023 00:32:51] "GET /openapi/swagger HTTP/1.1" 200 - - call_trace=C:\PUC-RIO\Sprint-1\BackEnd\puc-rio-mvp-sprint-1-back-end\venv\Lib\site-packages\werkzeug\_internal.py L224 
[2023-04-05 00:32:51,155] INFO _log() L224  127.0.0.1 - - [05/Apr/2023 00:32:51] "[36mGET /openapi/static/css/swagger-ui.css HTTP/1.1[0m" 304 - - call_trace=C:\PUC-RIO\Sprint-1\BackEnd\puc-rio-mvp-sprint-1-back-end\venv\Lib\site-packages\werkzeug\_internal.py L224 
[2023-04-05 00:32:51,159] INFO _log() L224  127.0.0.1 - - [05/Apr/2023 00:32:51] "[36mGET /openapi/static/js/swagger-ui-standalone-preset.js HTTP/1.1[0m" 304 - - call_trace=C:\PUC-RIO\Sprint-1\BackEnd\puc-rio-mvp-sprint-1-back-end\venv\Lib\site-packages\werkzeug\_internal.py L224 
[2023-04-05 00:32:51,159] INFO _log() L224  127.0.0.1 - - [05/Apr/2023 00:32:51] "[36mGET /openapi/static/js/swagger-ui-bundle.js HTTP/1.1[0m" 304 - - call_trace=C:\PUC-RIO\Sprint-1\BackEnd\puc-rio-mvp-sprint-1-back-end\venv\Lib\site-packages\werkzeug\_internal.py L224 
[2023-04-05 00:32:51,255] INFO _log() L224  127.0.0.1 - - [05/Apr/2023 00:32:51] "GET /openapi/openapi.json HTTP/1.1" 200 - - call_trace=C:\PUC-RIO\Sprint-1\BackEnd\puc-rio-mvp-sprint-1-back-end\venv\Lib\site-packages\werkzeug\_internal.py L224 
[2023-04-05 00:32:51,316] INFO _log() L224  127.0.0.1 - - [05/Apr/2023 00:32:51] "[36mGET /openapi/static/images/swagger.svg HTTP/1.1[0m" 304 - - call_trace=C:\PUC-RIO\Sprint-1\BackEnd\puc-rio-mvp-sprint-1-back-end\venv\Lib\site-packages\werkzeug\_internal.py L224 
[2023-04-05 00:32:55,297] WARNING add_agendamento() L75   erro <bound method SQLAlchemyError.__str__ of OperationalError('(sqlite3.OperationalError) table agendamento has no column named cliente_id')> - call_trace=C:\PUC-RIO\Sprint-1\BackEnd\puc-rio-mvp-sprint-1-back-end\app.py L75  
[2023-04-05 00:32:55,298] WARNING add_agendamento() L76   Erro ao adicionar o agendamento com data '2023-01-04 08:00:00 e cliente ID #Agendamento.cliente_id', Não foi possível salvar novo item :/ - call_trace=C:\PUC-RIO\Sprint-1\BackEnd\puc-rio-mvp-sprint-1-back-end\app.py L76  
[2023-04-05 00:32:55,299] INFO _log() L224  127.0.0.1 - - [05/Apr/2023 00:32:55] "[31m[1mPOST /agendamento HTTP/1.1[0m" 400 - - call_trace=C:\PUC-RIO\Sprint-1\BackEnd\puc-rio-mvp-sprint-1-back-end\venv\Lib\site-packages\werkzeug\_internal.py L224 
[2023-04-05 00:34:03,871] INFO _log() L224   * Running on all addresses (0.0.0.0)
   WARNING: This is a development server. Do not use it in a production deployment.
 * Running on http://127.0.0.1:5000
 * Running on http://192.168.15.138:5000 (Press CTRL+C to quit) - call_trace=C:\PUC-RIO\Sprint-1\BackEnd\puc-rio-mvp-sprint-1-back-end\venv\Lib\site-packages\werkzeug\_internal.py L224 
[2023-04-05 00:34:16,730] ERROR log_exception() L1449 Exception on /agendamento [POST] - call_trace=C:\PUC-RIO\Sprint-1\BackEnd\puc-rio-mvp-sprint-1-back-end\venv\Lib\site-packages\flask\app.py L1449
Traceback (most recent call last):
  File "C:\PUC-RIO\Sprint-1\BackEnd\puc-rio-mvp-sprint-1-back-end\venv\Lib\site-packages\flask\app.py", line 2073, in wsgi_app
    response = self.full_dispatch_request()
               ^^^^^^^^^^^^^^^^^^^^^^^^^^^^
  File "C:\PUC-RIO\Sprint-1\BackEnd\puc-rio-mvp-sprint-1-back-end\venv\Lib\site-packages\flask\app.py", line 1520, in full_dispatch_request
    return self.finalize_request(rv)
           ^^^^^^^^^^^^^^^^^^^^^^^^^
  File "C:\PUC-RIO\Sprint-1\BackEnd\puc-rio-mvp-sprint-1-back-end\venv\Lib\site-packages\flask\app.py", line 1539, in finalize_request
    response = self.make_response(rv)
               ^^^^^^^^^^^^^^^^^^^^^^
  File "C:\PUC-RIO\Sprint-1\BackEnd\puc-rio-mvp-sprint-1-back-end\venv\Lib\site-packages\flask\app.py", line 1714, in make_response
    rv = jsonify(rv)
         ^^^^^^^^^^^
  File "C:\PUC-RIO\Sprint-1\BackEnd\puc-rio-mvp-sprint-1-back-end\venv\Lib\site-packages\flask\json\__init__.py", line 302, in jsonify
    f"{dumps(data, indent=indent, separators=separators)}\n",
       ^^^^^^^^^^^^^^^^^^^^^^^^^^^^^^^^^^^^^^^^^^^^^^^^^
  File "C:\PUC-RIO\Sprint-1\BackEnd\puc-rio-mvp-sprint-1-back-end\venv\Lib\site-packages\flask\json\__init__.py", line 132, in dumps
    return _json.dumps(obj, **kwargs)
           ^^^^^^^^^^^^^^^^^^^^^^^^^^
  File "C:\Users\edumi\AppData\Local\Programs\Python\Python311\Lib\json\__init__.py", line 238, in dumps
    **kw).encode(obj)
          ^^^^^^^^^^^
  File "C:\Users\edumi\AppData\Local\Programs\Python\Python311\Lib\json\encoder.py", line 200, in encode
    chunks = self.iterencode(o, _one_shot=True)
             ^^^^^^^^^^^^^^^^^^^^^^^^^^^^^^^^^^
  File "C:\Users\edumi\AppData\Local\Programs\Python\Python311\Lib\json\encoder.py", line 258, in iterencode
    return _iterencode(o, 0)
           ^^^^^^^^^^^^^^^^^
  File "C:\PUC-RIO\Sprint-1\BackEnd\puc-rio-mvp-sprint-1-back-end\venv\Lib\site-packages\flask\json\__init__.py", line 51, in default
    return super().default(o)
           ^^^^^^^^^^^^^^^^^^
  File "C:\Users\edumi\AppData\Local\Programs\Python\Python311\Lib\json\encoder.py", line 180, in default
    raise TypeError(f'Object of type {o.__class__.__name__} '
TypeError: Object of type Cliente is not JSON serializable
[2023-04-05 00:34:16,742] INFO _log() L224  127.0.0.1 - - [05/Apr/2023 00:34:16] "[35m[1mPOST /agendamento HTTP/1.1[0m" 500 - - call_trace=C:\PUC-RIO\Sprint-1\BackEnd\puc-rio-mvp-sprint-1-back-end\venv\Lib\site-packages\werkzeug\_internal.py L224 
[2023-04-05 00:36:16,720] INFO _log() L224   * Running on all addresses (0.0.0.0)
   WARNING: This is a development server. Do not use it in a production deployment.
 * Running on http://127.0.0.1:5000
 * Running on http://192.168.15.138:5000 (Press CTRL+C to quit) - call_trace=C:\PUC-RIO\Sprint-1\BackEnd\puc-rio-mvp-sprint-1-back-end\venv\Lib\site-packages\werkzeug\_internal.py L224 
[2023-04-05 00:36:21,188] INFO _log() L224  127.0.0.1 - - [05/Apr/2023 00:36:21] "GET /openapi/swagger HTTP/1.1" 200 - - call_trace=C:\PUC-RIO\Sprint-1\BackEnd\puc-rio-mvp-sprint-1-back-end\venv\Lib\site-packages\werkzeug\_internal.py L224 
[2023-04-05 00:36:21,286] INFO _log() L224  127.0.0.1 - - [05/Apr/2023 00:36:21] "[36mGET /openapi/static/css/swagger-ui.css HTTP/1.1[0m" 304 - - call_trace=C:\PUC-RIO\Sprint-1\BackEnd\puc-rio-mvp-sprint-1-back-end\venv\Lib\site-packages\werkzeug\_internal.py L224 
[2023-04-05 00:36:21,295] INFO _log() L224  127.0.0.1 - - [05/Apr/2023 00:36:21] "[36mGET /openapi/static/js/swagger-ui-bundle.js HTTP/1.1[0m" 304 - - call_trace=C:\PUC-RIO\Sprint-1\BackEnd\puc-rio-mvp-sprint-1-back-end\venv\Lib\site-packages\werkzeug\_internal.py L224 
[2023-04-05 00:36:21,296] INFO _log() L224  127.0.0.1 - - [05/Apr/2023 00:36:21] "[36mGET /openapi/static/js/swagger-ui-standalone-preset.js HTTP/1.1[0m" 304 - - call_trace=C:\PUC-RIO\Sprint-1\BackEnd\puc-rio-mvp-sprint-1-back-end\venv\Lib\site-packages\werkzeug\_internal.py L224 
